<?xml version="1.0" ?>
<!-- This URDF was automatically created by SolidWorks to URDF Exporter! Originally created by Stephen Brawner (brawner@gmail.com) 
     Commit Version: 1.6.0-4-g7f85cfe  Build Version: 1.6.7995.38578
     For more information, please see http://wiki.ros.org/sw_urdf_exporter -->
<robot
  name="robot_arm" xmlns:xacro="http://ros.org/wiki/xacro">
  <xacro:macro name="body_color">
    <visual>
      <material>
        <ambient>0.796078431372549 0.819607843137255 0.933333333333333 1</ambient>
        <diffuse>0.796078431372549 0.819607843137255 0.933333333333333 1</diffuse>
        <specular>0.1 0.1 0.1 1</specular>
        <emissive>0 0 0 0</emissive>
      </material>
    </visual>
  </xacro:macro>
  <xacro:macro name="cap_color">
    <visual>
      <material>
        <ambient>0.482352941176471 0.792156862745098 1 1</ambient>
        <diffuse>0.482352941176471 0.792156862745098 1 1</diffuse>
        <specular>0.1 0.1 0.1 1</specular>
        <emissive>0 0 0 0</emissive>
      </material>
    </visual>
  </xacro:macro>
  <link name="world" />
  <link
    name="base_link">
    <inertial>
      <origin
        xyz="0.000818930716522579 -0.000818930139439305 0.0140278111957652"
        rpy="0 0 0" />
      <mass
        value="0.365058052116186" />
      <inertia
        ixx="0.00051380644225505"
        ixy="-1.25381433478329E-05"
        ixz="3.47062873674803E-08"
        iyy="0.000513806425545493"
        iyz="-3.47077199058619E-08"
        izz="0.000833137426033134" />
    </inertial>
    <visual>
      <origin
        xyz="0 0 0"
        rpy="0 0 0" />
      <geometry>
        <mesh
          filename="package://project_two/meshes/base_link.STL" />
      </geometry>
      <material
        name="">
        <color
          rgba="0.792156862745098 0.819607843137255 0.933333333333333 1" />
      </material>
    </visual>
    <collision>
      <origin
        xyz="0 0 0"
        rpy="0 0 0" />
      <geometry>
        <mesh
          filename="package://project_two/meshes/base_link.STL" />
      </geometry>
    </collision>
  </link>
  <joint name="fixed_base" type="fixed">
    <parent link="world" />
    <child link="base_link" />
  </joint>
  <link
    name="link_1">
    <inertial>
      <origin
        xyz="-2.01994143885152E-08 0.0147276350283187 0.0810226747554533"
        rpy="0 0 0" />
      <mass
        value="1.21747724894722" />
      <inertia
        ixx="0.00255263718574973"
        ixy="7.20416731900228E-09"
        ixz="-3.70618686006579E-09"
        iyy="0.00210897804842468"
        iyz="-0.000297852263493"
        izz="0.00266305849374601" />
    </inertial>
    <visual>
      <origin
        xyz="0 0 0"
        rpy="0 0 0" />
      <geometry>
        <mesh
          filename="package://project_two/meshes/link_1.STL" />
      </geometry>
      <material
        name="">
        <color
          rgba="0.796078431372549 0.819607843137255 0.933333333333333 1" />
      </material>
    </visual>
    <collision>
      <origin
        xyz="0 0 0"
        rpy="0 0 0" />
      <geometry>
        <mesh
          filename="package://project_two/meshes/link_1.STL" />
      </geometry>
    </collision>
  </link>
  <joint
    name="joint_1"
    type="revolute">
    <origin
      xyz="0 0 0"
      rpy="0 0 0" />
    <parent
      link="base_link" />
    <child
      link="link_1" />
    <axis
      xyz="0 0 1" />
    <limit
      lower="-3.1416"
      upper="3.1416"
      effort="0"
      velocity="0" />
    <dynamics damping="0.7" friction="1.0"/>
  </joint>
  <link
    name="link_1_cap">
    <inertial>
      <origin
        xyz="1.42302771372066E-07 -0.00806677437392857 0.138671119640996"
        rpy="0 0 0" />
      <mass
        value="0.330021171721498" />
      <inertia
        ixx="0.000313864807069818"
        ixy="1.39841178897165E-09"
        ixz="2.28303347219796E-10"
        iyy="0.000335340499862343"
        iyz="-7.39635181857418E-05"
        izz="0.000541751266552296" />
    </inertial>
    <visual>
      <origin
        xyz="0 0 0"
        rpy="0 0 0" />
      <geometry>
        <mesh
          filename="package://project_two/meshes/link_1_cap.STL" />
      </geometry>
      <material
        name="">
        <color
          rgba="0.482352941176471 0.792156862745098 1 1" />
      </material>
    </visual>
    <collision>
      <origin
        xyz="0 0 0"
        rpy="0 0 0" />
      <geometry>
        <mesh
          filename="package://project_two/meshes/link_1_cap.STL" />
      </geometry>
    </collision>
  </link>
  <joint name="link_1_cap_joint" type="prismatic">
      <origin xyz="0 0 0" rpy="0 0 0" />
      <parent link="link_1" />
      <child link="link_1_cap" />
      <axis xyz="1 0 0" />
      <limit lower="0" upper="0" effort="0" velocity="0" />
  </joint>
  <link
    name="link_2">
    <inertial>
      <origin
        xyz="5.28224377692258E-09 -0.212110309879065 0.129614412124911"
        rpy="0 0 0" />
      <mass
        value="4.0347772255313" />
      <inertia
        ixx="0.112004707514996"
        ixy="1.49514812132019E-08"
        ixz="-4.44365415979749E-10"
        iyy="0.00580966202350412"
        iyz="1.87193857431351E-05"
        izz="0.1121524014166" />
    </inertial>
    <visual>
      <origin
        xyz="0 0 0"
        rpy="0 0 0" />
      <geometry>
        <mesh
          filename="package://project_two/meshes/link_2.STL" />
      </geometry>
      <material
        name="">
        <color
          rgba="0.792156862745098 0.819607843137255 0.933333333333333 1" />
      </material>
    </visual>
    <collision>
      <origin
        xyz="0 0 0"
        rpy="0 0 0" />
      <geometry>
        <mesh
          filename="package://project_two/meshes/link_2.STL" />
      </geometry>
    </collision>
  </link>
  <joint
    name="joint_2"
    type="revolute">
    <origin
      xyz="0 0 0.09"
      rpy="-1.5707963267949 0 0" />
    <parent
      link="link_1" />
    <child
      link="link_2" />
    <axis
      xyz="0 0 1" />
    <limit
      lower="-3.1416"
      upper="3.1416"
      effort="0"
      velocity="0" />
    <dynamics damping="0.7" friction="1.0"/>
  </joint>
  <link
    name="link_2_cap_1">
    <inertial>
      <origin
        xyz="-1.42302772727024E-07 0.00806677437392862 0.183671119640996"
        rpy="0 0 0" />
      <mass
        value="0.330021171721499" />
      <inertia
        ixx="0.000313864807069819"
        ixy="1.39841178841114E-09"
        ixz="-2.28303348779531E-10"
        iyy="0.000335340499862345"
        iyz="7.39635181857419E-05"
        izz="0.000541751266552297" />
    </inertial>
    <visual>
      <origin
        xyz="0 0 0"
        rpy="0 0 0" />
      <geometry>
        <mesh
          filename="package://project_two/meshes/link_2_cap_1.STL" />
      </geometry>
      <material
        name="">
        <color
          rgba="0.482352941176471 0.792156862745098 1 1" />
      </material>
    </visual>
    <collision>
      <origin
        xyz="0 0 0"
        rpy="0 0 0" />
      <geometry>
        <mesh
          filename="package://project_two/meshes/link_2_cap_1.STL" />
      </geometry>
    </collision>
  </link>
  <joint name="link_2_cap_1_joint" type="prismatic">
      <origin xyz="0 0 0" rpy="0 0 0" />
      <parent link="link_2" />
      <child link="link_2_cap_1" />
      <axis xyz="1 0 0" />
      <limit lower="0" upper="0" effort="0" velocity="0" />
  </joint>
  <link
    name="link_2_cap_2">
    <inertial>
      <origin
        xyz="1.42302768078402E-07 -0.433066774373929 0.183671119640996"
        rpy="0 0 0" />
      <mass
        value="0.330021171721498" />
      <inertia
        ixx="0.000313864807069817"
        ixy="1.39841178881497E-09"
        ixz="2.28303347202352E-10"
        iyy="0.00033534049986234"
        iyz="-7.39635181857418E-05"
        izz="0.000541751266552293" />
    </inertial>
    <visual>
      <origin
        xyz="0 0 0"
        rpy="0 0 0" />
      <geometry>
        <mesh
          filename="package://project_two/meshes/link_2_cap_2.STL" />
      </geometry>
      <material
        name="">
        <color
          rgba="0.482352941176471 0.792156862745098 1 1" />
      </material>
    </visual>
    <collision>
      <origin
        xyz="0 0 0"
        rpy="0 0 0" />
      <geometry>
        <mesh
          filename="package://project_two/meshes/link_2_cap_2.STL" />
      </geometry>
    </collision>
  </link>
  <joint name="link_2_cap_2_joint" type="prismatic">
    <origin xyz="0 0 0" rpy="0 0 0" />
    <parent link="link_2" />
    <child link="link_2_cap_2" />
    <axis xyz="1 0 0" />
    <limit lower="0" upper="0" effort="0" velocity="0" />
  </joint>
  <link
    name="link_3">
    <inertial>
      <origin
        xyz="0.170735221821587 -3.25840811083973E-08 0.0224616676097575"
        rpy="0 0 0" />
      <mass
        value="2.32742946004391" />
      <inertia
        ixx="0.00230746896110105"
        ixy="3.4207779530455E-08"
        ixz="0.00199952758100954"
        iyy="0.0464994251527757"
        iyz="-6.32534417374874E-10"
        izz="0.0462634575355965" />
    </inertial>
    <visual>
      <origin
        xyz="0 0 0"
        rpy="0 0 0" />
      <geometry>
        <mesh
          filename="package://project_two/meshes/link_3.STL" />
      </geometry>
      <material
        name="">
        <color
          rgba="0.788235294117647 0.819607843137255 0.933333333333333 1" />
      </material>
    </visual>
    <collision>
      <origin
        xyz="0 0 0"
        rpy="0 0 0" />
      <geometry>
        <mesh
          filename="package://project_two/meshes/link_3.STL" />
      </geometry>
    </collision>
  </link>
  <joint
    name="joint_3"
    type="revolute">
    <origin
      xyz="0 -0.425 0"
      rpy="0 0 -1.5707963267949" />
    <parent
      link="link_2" />
    <child
      link="link_3" />
    <axis
      xyz="0 0 1" />
    <limit
      lower="-3.1416"
      upper="3.1416"
      effort="0"
      velocity="0" />
    <dynamics damping="0.7" friction="1.0"/>
  </joint>
  <link
    name="link_3_cap">
    <inertial>
      <origin
        xyz="0.397027900194223 4.22453817605446E-09 -0.0224353204034724"
        rpy="0 0 0" />
      <mass
        value="0.129962415869425" />
      <inertia
        ixx="6.00214466648602E-05"
        ixy="-3.03760968261969E-11"
        ixz="-9.23419401157055E-06"
        iyy="5.70550178521916E-05"
        iyz="-1.90648141611329E-11"
        izz="9.13995513971888E-05" />
    </inertial>
    <visual>
      <origin
        xyz="0 0 0"
        rpy="0 0 0" />
      <geometry>
        <mesh
          filename="package://project_two/meshes/link_3_cap.STL" />
      </geometry>
      <material
        name="">
        <color
          rgba="0.482352941176471 0.792156862745098 1 1" />
      </material>
    </visual>
    <collision>
      <origin
        xyz="0 0 0"
        rpy="0 0 0" />
      <geometry>
        <mesh
          filename="package://project_two/meshes/link_3_cap.STL" />
      </geometry>
    </collision>
  </link>
  <joint name="link_3_cap_joint" type="prismatic">
      <origin xyz="0 0 0" rpy="0 0 0" />
      <parent link="link_3" />
      <child link="link_3_cap" />
      <axis xyz="1 0 0" />
      <limit lower="0" upper="0" effort="0" velocity="0" />
  </joint>
  <link
    name="link_4">
    <inertial>
      <origin
        xyz="2.08868109703753E-08 -0.0104204825260419 0.00625096574296091"
        rpy="0 0 0" />
      <mass
        value="0.361403101490435" />
      <inertia
        ixx="0.000347379241813699"
        ixy="-4.53086892636865E-10"
        ixz="1.81738584051007E-10"
        iyy="0.000274440792632068"
        iyz="-3.88893030652286E-05"
        izz="0.000346423259403175" />
    </inertial>
    <visual>
      <origin
        xyz="0 0 0"
        rpy="0 0 0" />
      <geometry>
        <mesh
          filename="package://project_two/meshes/link_4.STL" />
      </geometry>
      <material
        name="">
        <color
          rgba="0.796078431372549 0.819607843137255 0.933333333333333 1" />
      </material>
    </visual>
    <collision>
      <origin
        xyz="0 0 0"
        rpy="0 0 0" />
      <geometry>
        <mesh
          filename="package://project_two/meshes/link_4.STL" />
      </geometry>
    </collision>
  </link>
  <joint
    name="joint_4"
    type="revolute">
    <origin
      xyz="0.39225 0 0.1099"
      rpy="1.5707963267949 0 1.5707963267949" />
    <parent
      link="link_3" />
    <child
      link="link_4" />
    <axis
      xyz="0 1 0" />
    <limit
      lower="-3.1416"
      upper="3.1416"
      effort="0"
      velocity="0" />
    <dynamics damping="0.7" friction="1.0"/>
  </joint>
  <link
    name="link_4_cap">
    <inertial>
      <origin
        xyz="-4.22452399082911E-09 0.00477790019422317 -0.0376853204034723"
        rpy="0 0 0" />
      <mass
        value="0.129962415869424" />
      <inertia
        ixx="5.70550178521915E-05"
        ixy="3.03760968441512E-11"
        ixz="1.90648139359578E-11"
        iyy="6.00214466648598E-05"
        iyz="-9.23419401157052E-06"
        izz="9.13995513971885E-05" />
    </inertial>
    <visual>
      <origin
        xyz="0 0 0"
        rpy="0 0 0" />
      <geometry>
        <mesh
          filename="package://project_two/meshes/link_4_cap.STL" />
      </geometry>
      <material
        name="">
        <color
          rgba="0.482352941176471 0.792156862745098 1 1" />
      </material>
    </visual>
    <collision>
      <origin
        xyz="0 0 0"
        rpy="0 0 0" />
      <geometry>
        <mesh
          filename="package://project_two/meshes/link_4_cap.STL" />
      </geometry>
    </collision>
  </link>
  <joint name="link_4_cap_joint" type="prismatic">
      <origin xyz="0 0 0" rpy="0 0 0" />
      <parent link="link_4" />
      <child link="link_4_cap" />
      <axis xyz="1 0 0" />
      <limit lower="0" upper="0" effort="0" velocity="0" />
  </joint>
  <link
    name="link_5">
    <inertial>
      <origin
        xyz="-2.08867958526121E-08 0.0104204825260416 0.00625096574296091"
        rpy="0 0 0" />
      <mass
        value="0.361403101490434" />
      <inertia
        ixx="0.000347379241813699"
        ixy="-4.53086893620097E-10"
        ixz="-1.81738583678317E-10"
        iyy="0.000274440792632068"
        iyz="3.88893030652285E-05"
        izz="0.000346423259403175" />
    </inertial>
    <visual>
      <origin
        xyz="0 0 0"
        rpy="0 0 0" />
      <geometry>
        <mesh
          filename="package://project_two/meshes/link_5.STL" />
      </geometry>
      <material
        name="">
        <color
          rgba="0.792156862745098 0.819607843137255 0.933333333333333 1" />
      </material>
    </visual>
    <collision>
      <origin
        xyz="0 0 0"
        rpy="0 0 0" />
      <geometry>
        <mesh
          filename="package://project_two/meshes/link_5.STL" />
      </geometry>
    </collision>
  </link>
  <joint
    name="joint_5"
    type="revolute">
    <origin
      xyz="0 0 0.0946499999999998"
      rpy="-1.5707963267949 0 0" />
    <parent
      link="link_4" />
    <child
      link="link_5" />
    <axis
      xyz="0 -1 0" />
    <limit
      lower="-3.1416"
      upper="3.1416"
      effort="0"
      velocity="0" />
    <dynamics damping="0.7" friction="1.0"/>
  </joint>
  <link
    name="link_5_cap">
    <inertial>
      <origin
        xyz="4.22454006210197E-09 -0.00477790019422364 -0.0376853204034798"
        rpy="0 0 0" />
      <mass
        value="0.129962415869425" />
      <inertia
        ixx="5.70550178521917E-05"
        ixy="3.03760968117855E-11"
        ixz="-1.90648140818228E-11"
        iyy="6.00214466648601E-05"
        iyz="9.2341940115703E-06"
        izz="9.13995513971891E-05" />
    </inertial>
    <visual>
      <origin
        xyz="0 0 0"
        rpy="0 0 0" />
      <geometry>
        <mesh
          filename="package://project_two/meshes/link_5_cap.STL" />
      </geometry>
      <material
        name="">
        <color
          rgba="0.482352941176471 0.792156862745098 1 1" />
      </material>
    </visual>
    <collision>
      <origin
        xyz="0 0 0"
        rpy="0 0 0" />
      <geometry>
        <mesh
          filename="package://project_two/meshes/link_5_cap.STL" />
      </geometry>
    </collision>
  </link>
  <joint name="link_5_cap_joint" type="prismatic">
      <origin xyz="0 0 0" rpy="0 0 0" />
      <parent link="link_5" />
      <child link="link_5_cap" />
      <axis xyz="1 0 0" />
      <limit lower="0" upper="0" effort="0" velocity="0" />
  </joint>
  <link
    name="link_6">
    <inertial>
      <origin
        xyz="6.47588935142619E-13 -3.74367203903603E-13 -0.0211694949353718"
        rpy="0 0 0" />
      <mass
        value="0.148286360656985" />
      <inertia
        ixx="7.71175301770416E-05"
        ixy="6.59118773723624E-22"
        ixz="-7.79562353002313E-20"
        iyy="7.71175301770417E-05"
        iyz="7.0513121553266E-22"
        izz="9.81906446643079E-05" />
    </inertial>
    <visual>
      <origin
        xyz="0 0 0"
        rpy="0 0 0" />
      <geometry>
        <mesh
          filename="package://project_two/meshes/link_6.STL" />
      </geometry>
      <material
        name="">
        <color
          rgba="0.792156862745098 0.819607843137255 0.933333333333333 1" />
      </material>
    </visual>
    <collision>
      <origin
        xyz="0 0 0"
        rpy="0 0 0" />
      <geometry>
        <mesh
          filename="package://project_two/meshes/link_6.STL" />
      </geometry>
    </collision>
  </link>
  <joint
    name="joint_6"
    type="revolute">
    <origin
      xyz="0 0 0.081499999999992"
      rpy="0 0 0" />
    <parent
      link="link_5" />
    <child
      link="link_6" />
    <axis
      xyz="0 0 -1" />
    <limit
      lower="-3.1416"
      upper="3.1416"
      effort="0"
      velocity="0" />
    <dynamics damping="0.7" friction="1.0"/>
  </joint>
  <gazebo reference="base_link">
    <xacro:body_color />
  </gazebo>
  <gazebo reference="link_1">
    <xacro:body_color />
  </gazebo>
  <gazebo reference="link_2">
    <xacro:body_color />
  </gazebo>
  <gazebo reference="link_3">
    <xacro:body_color />
  </gazebo>
  <gazebo reference="link_4">
    <xacro:body_color />
  </gazebo>
  <gazebo reference="link_5">
    <xacro:body_color />
  </gazebo>
  <gazebo reference="link_6">
    <xacro:body_color />
  </gazebo>
  <gazebo reference="link_1_cap">
    <xacro:cap_color />
  </gazebo>
  <gazebo reference="link_2_cap_1">
    <xacro:cap_color />
  </gazebo>
  <gazebo reference="link_2_cap_2">
    <xacro:cap_color />
  </gazebo>
  <gazebo reference="link_3_cap">
    <xacro:cap_color />
  </gazebo>
  <gazebo reference="link_4_cap">
    <xacro:cap_color />
  </gazebo>
  <gazebo reference="link_5_cap">
    <xacro:cap_color />
  </gazebo>
  <ros2_control name="GazeboSystem" type="system">
    <hardware>
      <plugin>gazebo_ros2_control/GazeboSystem</plugin>
    </hardware>
    <joint name="joint_1">
        <command_interface name="position">
            <param name="min">-3.14</param>
            <param name="max">3.14</param>
        </command_interface>
        <state_interface name="position"/>
    </joint>
    <joint name="joint_2">
        <command_interface name="position">
            <param name="min">-3.14</param>
            <param name="max">3.14</param>
        </command_interface>
        <state_interface name="position"/>
    </joint>
    <joint name="joint_3">
        <command_interface name="position">
            <param name="min">-3.14</param>
            <param name="max">3.14</param>
        </command_interface>
        <state_interface name="position"/>
    </joint>
    <joint name="joint_4">
        <command_interface name="position">
            <param name="min">-3.14</param>
            <param name="max">3.14</param>
        </command_interface>
        <state_interface name="position"/>
    </joint>
    <joint name="joint_5">
        <command_interface name="position">
            <param name="min">-3.14</param>
            <param name="max">3.14</param>
        </command_interface>
        <state_interface name="position"/>
    </joint>
    <joint name="joint_6">
        <command_interface name="position">
            <param name="min">-3.14</param>
            <param name="max">3.14</param>
        </command_interface>
        <state_interface name="position"/>
    </joint>
  </ros2_control>
  <gazebo>
    <plugin filename="libgazebo_ros2_control.so" name="gazebo_ros2_control">
      <parameters>$(find project_two)/config/control.yaml</parameters>
    </plugin>
  </gazebo>
  <gazebo reference="joint_1">
    <implicitSpringDamper>true</implicitSpringDamper>
  </gazebo>
  <gazebo reference="joint_2">
    <implicitSpringDamper>true</implicitSpringDamper>
  </gazebo>
  <gazebo reference="joint_3">
    <implicitSpringDamper>true</implicitSpringDamper>
  </gazebo>
  <gazebo reference="joint_4">
    <implicitSpringDamper>true</implicitSpringDamper>
  </gazebo>
  <gazebo reference="joint_5">
    <implicitSpringDamper>true</implicitSpringDamper>
  </gazebo>
  <gazebo reference="joint_6">
    <implicitSpringDamper>true</implicitSpringDamper>
  </gazebo>
</robot>