<?xml version="1.0" ?>
<robot
  name="robot_arm" xmlns:xacro="http://ros.org/wiki/xacro">
  
  <!-- Gazebo Color Plugins -->
  <xacro:macro name="body_color">
    <visual>
      <material>
        <ambient>0.796078431372549 0.819607843137255 0.933333333333333 1</ambient>
        <diffuse>0.796078431372549 0.819607843137255 0.933333333333333 1</diffuse>
        <specular>0.1 0.1 0.1 1</specular>
        <emissive>0 0 0 0</emissive>
      </material>
    </visual>
  </xacro:macro>
  <xacro:macro name="cap_color">
    <visual>
      <material>
        <ambient>0.482352941176471 0.792156862745098 1 1</ambient>
        <diffuse>0.482352941176471 0.792156862745098 1 1</diffuse>
        <specular>0.1 0.1 0.1 1</specular>
        <emissive>0 0 0 0</emissive>
      </material>
    </visual>
  </xacro:macro>
  <xacro:macro name="base_color">
    <visual>
      <material>
        <ambient>0.41569 0.67451 1 1</ambient>
        <diffuse>0.41569 0.67451 1 1</diffuse>
        <specular>0.1 0.1 0.1 1</specular>
        <emissive>0 0 0 0</emissive>
      </material>
    </visual>
  </xacro:macro>
  <xacro:macro name="tool_color">
    <visual>
      <material>
        <ambient>0.19608 0.19608 0.19608 1</ambient>
        <diffuse>0.19608 0.19608 0.19608 1</diffuse>
        <specular>0.1 0.1 0.1 1</specular>
        <emissive>0 0 0 0</emissive>
      </material>
    </visual>
  </xacro:macro>

  <!-- World Link for Fixed Base -->
  <link name="world" />

  <link
    name="base_link">
    <inertial>
      <origin
        xyz="2.9549E-17 -0.00030197 0.11134"
        rpy="0 0 0" />
      <mass
        value="17.843" />
      <inertia
        ixx="0.87104"
        ixy="-3.2142E-07"
        ixz="-9.442E-18"
        iyy="0.48766"
        iyz="0.00055476"
        izz="0.98951" />
    </inertial>
    <visual>
      <origin
        xyz="0 0 0"
        rpy="0 0 0" />
      <geometry>
        <mesh
          filename="package://project_two/meshes/base_link.STL" />
      </geometry>
      <material
        name="">
        <color
          rgba="0.41569 0.67451 1 1" />
      </material>
    </visual>
    <collision>
      <origin
        xyz="0 0 0"
        rpy="0 0 0" />
      <geometry>
        <mesh
          filename="package://project_two/meshes/base_link.STL" />
      </geometry>
    </collision>
  </link>

  <!-- World Joint For Fixed Base -->
  <joint name="fixed_base" type="fixed">
    <parent link="world" />
    <child link="base_link" />
  </joint>

    
  
  <joint
    name="camera_joint"
    type="fixed">
    <origin
      xyz="0 -0.120050000000001 0.2983"
      rpy="1.5707963267949 0 0" />
    <parent
      link="base_link" />
    <child
      link="camera_link" />
    <axis
      xyz="0 0 0" />
  </joint>
  
  <link
    name="camera_link">
    <inertial>
      <origin
        xyz="-3.8492E-19 0.0043066 -0.0086877"
        rpy="0 0 0" />
      <mass
        value="0.011" />
      <inertia
        ixx="1.206E-06"
        ixy="1.0009E-22"
        ixz="-5.0667E-23"
        iyy="1.4269E-06"
        iyz="8.5819E-08"
        izz="1.3248E-06" />
    </inertial>
    <visual>
      <origin
        xyz="0 0 0"
        rpy="0 0 0" />
      <geometry>
        <mesh
          filename="package://project_two/meshes/camera_link.STL" />
      </geometry>
      <material
        name="">
        <color
          rgba="0.19608 0.19608 0.19608 1" />
      </material>
    </visual>
    <collision>
      <origin
        xyz="0 0 0"
        rpy="0 0 0" />
      <geometry>
        <mesh
          filename="package://project_two/meshes/camera_link.STL" />
      </geometry>
    </collision>
  </link>

  <!-- Dummy link to correct Image Reference Frame for Camera -->
  <joint name="camera_optical_joint" type="fixed">
      <origin xyz="0 0 0" rpy="0 -1.5707 -1.5707963267949" />
      <parent link="camera_link" />
      <child link="camera_link_optical" />
  </joint>
  <link name="camera_link_optical"></link>

  
  <link
    name="link_0">
    <inertial>
      <origin
        xyz="0.00081893 -0.00081893 0.50768"
        rpy="0 0 0" />
      <mass
        value="0.36506" />
      <inertia
        ixx="0.00051381"
        ixy="-1.2538E-05"
        ixz="3.4706E-08"
        iyy="0.00051381"
        iyz="-3.4708E-08"
        izz="0.00083314" />
    </inertial>
    <visual>
      <origin
        xyz="0 0 0"
        rpy="0 0 0" />
      <geometry>
        <mesh
          filename="package://project_two/meshes/link_0.STL" />
      </geometry>
      <material
        name="">
        <color
          rgba="0.79216 0.81961 0.93333 1" />
      </material>
    </visual>
    <collision>
      <origin
        xyz="0 0 0"
        rpy="0 0 0" />
      <geometry>
        <mesh
          filename="package://project_two/meshes/link_0.STL" />
      </geometry>
    </collision>
  </link>
  <joint
    name="joint_0"
    type="fixed">
    <origin
      xyz="0 0 0"
      rpy="0 0 0" />
    <parent
      link="base_link" />
    <child
      link="link_0" />
    <axis
      xyz="0 0 0" />
  </joint>
  <link
    name="link_1">
    <inertial>
      <origin
        xyz="-1.7916E-08 0.014728 0.57467"
        rpy="0 0 0" />
      <mass
        value="1.2175" />
      <inertia
        ixx="0.0025526"
        ixy="5.0045E-09"
        ixz="5.1533E-10"
        iyy="0.002109"
        iyz="-0.00029785"
        izz="0.0026631" />
    </inertial>
    <visual>
      <origin
        xyz="0 0 0"
        rpy="0 0 0" />
      <geometry>
        <mesh
          filename="package://project_two/meshes/link_1.STL" />
      </geometry>
      <material
        name="">
        <color
          rgba="0.79608 0.81961 0.93333 1" />
      </material>
    </visual>
    <collision>
      <origin
        xyz="0 0 0"
        rpy="0 0 0" />
      <geometry>
        <mesh
          filename="package://project_two/meshes/link_1.STL" />
      </geometry>
    </collision>
  </link>
  <joint
    name="joint_1"
    type="revolute">
    <origin
      xyz="0 0 0"
      rpy="0 0 0" />
    <parent
      link="link_0" />
    <child
      link="link_1" />
    <axis
      xyz="0 0 1" />
    <limit
      lower="-3.1416"
      upper="3.1416"
      effort="0"
      velocity="0" />

      <!-- Added Joint Dynamics to Prevent Separation -->
      <dynamics damping="0.7" friction="1.0"/>

  </joint>
  <link
    name="link_1_cap">
    <inertial>
      <origin
        xyz="1.423E-07 -0.0080668 0.63232"
        rpy="0 0 0" />
      <mass
        value="0.33002" />
      <inertia
        ixx="0.00031386"
        ixy="1.3984E-09"
        ixz="2.283E-10"
        iyy="0.00033534"
        iyz="-7.3964E-05"
        izz="0.00054175" />
    </inertial>
    <visual>
      <origin
        xyz="0 0 0"
        rpy="0 0 0" />
      <geometry>
        <mesh
          filename="package://project_two/meshes/link_1_cap.STL" />
      </geometry>
      <material
        name="">
        <color
          rgba="0.48235 0.79216 1 1" />
      </material>
    </visual>
    <collision>
      <origin
        xyz="0 0 0"
        rpy="0 0 0" />
      <geometry>
        <mesh
          filename="package://project_two/meshes/link_1_cap.STL" />
      </geometry>
    </collision>
  </link>
  <joint
    name="link_1_cap_joint"
    type="prismatic">
    <origin
      xyz="0 0 0"
      rpy="0 0 0" />
    <parent
      link="link_1" />
    <child
      link="link_1_cap" />
    <axis
      xyz="0 0 1" />
    <limit
      lower="0"
      upper="0"
      effort="0"
      velocity="0" />
  </joint>
  <link
    name="link_2">
    <inertial>
      <origin
        xyz="5.2822E-09 -0.21211 0.12961"
        rpy="0 0 0" />
      <mass
        value="4.0348" />
      <inertia
        ixx="0.112"
        ixy="1.4951E-08"
        ixz="-4.4437E-10"
        iyy="0.0058097"
        iyz="1.8719E-05"
        izz="0.11215" />
    </inertial>
    <visual>
      <origin
        xyz="0 0 0"
        rpy="0 0 0" />
      <geometry>
        <mesh
          filename="package://project_two/meshes/link_2.STL" />
      </geometry>
      <material
        name="">
        <color
          rgba="0.79216 0.81961 0.93333 1" />
      </material>
    </visual>
    <collision>
      <origin
        xyz="0 0 0"
        rpy="0 0 0" />
      <geometry>
        <mesh
          filename="package://project_two/meshes/link_2.STL" />
      </geometry>
    </collision>
  </link>
  <joint
    name="joint_2"
    type="revolute">
    <origin
      xyz="0 0 0.58365"
      rpy="-1.57079632679489 0 0" />
    <parent
      link="link_1" />
    <child
      link="link_2" />
    <axis
      xyz="0 0 1" />
    <limit
      lower="-3.1416"
      upper="3.1416"
      effort="0"
      velocity="0" />

      <!-- Added Joint Dynamics to Prevent Separation -->
      <dynamics damping="0.7" friction="1.0"/>
  </joint>
  <link
    name="link_2_cap_1">
    <inertial>
      <origin
        xyz="-1.423E-07 0.0080668 0.18367"
        rpy="0 0 0" />
      <mass
        value="0.33002" />
      <inertia
        ixx="0.00031386"
        ixy="1.3984E-09"
        ixz="-2.283E-10"
        iyy="0.00033534"
        iyz="7.3964E-05"
        izz="0.00054175" />
    </inertial>
    <visual>
      <origin
        xyz="0 0 0"
        rpy="0 0 0" />
      <geometry>
        <mesh
          filename="package://project_two/meshes/link_2_cap_1.STL" />
      </geometry>
      <material
        name="">
        <color
          rgba="0.48235 0.79216 1 1" />
      </material>
    </visual>
    <collision>
      <origin
        xyz="0 0 0"
        rpy="0 0 0" />
      <geometry>
        <mesh
          filename="package://project_two/meshes/link_2_cap_1.STL" />
      </geometry>
    </collision>
  </link>
  <joint
    name="link_2_cap_1_joint"
    type="prismatic">
    <origin
      xyz="0 0 0"
      rpy="0 0 0" />
    <parent
      link="link_2" />
    <child
      link="link_2_cap_1" />
    <axis
      xyz="0 0 1" />
    <limit
      lower="0"
      upper="0"
      effort="0"
      velocity="0" />
  </joint>
  <link
    name="link_2_cap_2">
    <inertial>
      <origin
        xyz="1.423E-07 -0.43307 0.18367"
        rpy="0 0 0" />
      <mass
        value="0.33002" />
      <inertia
        ixx="0.00031386"
        ixy="1.3984E-09"
        ixz="2.283E-10"
        iyy="0.00033534"
        iyz="-7.3964E-05"
        izz="0.00054175" />
    </inertial>
    <visual>
      <origin
        xyz="0 0 0"
        rpy="0 0 0" />
      <geometry>
        <mesh
          filename="package://project_two/meshes/link_2_cap_2.STL" />
      </geometry>
      <material
        name="">
        <color
          rgba="0.48235 0.79216 1 1" />
      </material>
    </visual>
    <collision>
      <origin
        xyz="0 0 0"
        rpy="0 0 0" />
      <geometry>
        <mesh
          filename="package://project_two/meshes/link_2_cap_2.STL" />
      </geometry>
    </collision>
  </link>
  <joint
    name="link_2_cap_2_joint"
    type="prismatic">
    <origin
      xyz="0 0 0"
      rpy="0 0 0" />
    <parent
      link="link_2" />
    <child
      link="link_2_cap_2" />
    <axis
      xyz="0 0 1" />
    <limit
      lower="0"
      upper="0"
      effort="0"
      velocity="0" />
  </joint>
  <link
    name="link_3">
    <inertial>
      <origin
        xyz="0.17074 -3.2584E-08 0.022462"
        rpy="0 0 0" />
      <mass
        value="2.3274" />
      <inertia
        ixx="0.0023075"
        ixy="3.4208E-08"
        ixz="0.0019995"
        iyy="0.046499"
        iyz="-6.3253E-10"
        izz="0.046263" />
    </inertial>
    <visual>
      <origin
        xyz="0 0 0"
        rpy="0 0 0" />
      <geometry>
        <mesh
          filename="package://project_two/meshes/link_3.STL" />
      </geometry>
      <material
        name="">
        <color
          rgba="0.78824 0.81961 0.93333 1" />
      </material>
    </visual>
    <collision>
      <origin
        xyz="0 0 0"
        rpy="0 0 0" />
      <geometry>
        <mesh
          filename="package://project_two/meshes/link_3.STL" />
      </geometry>
    </collision>
  </link>
  <joint
    name="joint_3"
    type="revolute">
    <origin
      xyz="0 -0.425 0"
      rpy="0 0 -1.5707963267949" />
    <parent
      link="link_2" />
    <child
      link="link_3" />
    <axis
      xyz="0 0 1" />
    <limit
      lower="-3.1416"
      upper="3.1416"
      effort="0"
      velocity="0" />

      <!-- Added Joint Dynamics to Prevent Separation -->
      <dynamics damping="0.7" friction="1.0"/>
  </joint>
  <link
    name="link_3_cap">
    <inertial>
      <origin
        xyz="0.39703 4.2245E-09 -0.022435"
        rpy="0 0 0" />
      <mass
        value="0.12996" />
      <inertia
        ixx="6.0021E-05"
        ixy="-3.0376E-11"
        ixz="-9.2342E-06"
        iyy="5.7055E-05"
        iyz="-1.9065E-11"
        izz="9.14E-05" />
    </inertial>
    <visual>
      <origin
        xyz="0 0 0"
        rpy="0 0 0" />
      <geometry>
        <mesh
          filename="package://project_two/meshes/link_3_cap.STL" />
      </geometry>
      <material
        name="">
        <color
          rgba="0.48235 0.79216 1 1" />
      </material>
    </visual>
    <collision>
      <origin
        xyz="0 0 0"
        rpy="0 0 0" />
      <geometry>
        <mesh
          filename="package://project_two/meshes/link_3_cap.STL" />
      </geometry>
    </collision>
  </link>
  <joint
    name="link_3_cap_joint"
    type="prismatic">
    <origin
      xyz="0 0 0"
      rpy="0 0 0" />
    <parent
      link="link_3" />
    <child
      link="link_3_cap" />
    <axis
      xyz="0 0 1" />
    <limit
      lower="0"
      upper="0"
      effort="0"
      velocity="0" />
  </joint>
  <link
    name="link_4">
    <inertial>
      <origin
        xyz="0.006251 2.0887E-08 0.09948"
        rpy="0 0 0" />
      <mass
        value="0.3614" />
      <inertia
        ixx="0.00034642"
        ixy="1.8174E-10"
        ixz="-3.8889E-05"
        iyy="0.00034738"
        iyz="-4.5309E-10"
        izz="0.00027444" />
    </inertial>
    <visual>
      <origin
        xyz="0 0 0"
        rpy="0 0 0" />
      <geometry>
        <mesh
          filename="package://project_two/meshes/link_4.STL" />
      </geometry>
      <material
        name="">
        <color
          rgba="0.79608 0.81961 0.93333 1" />
      </material>
    </visual>
    <collision>
      <origin
        xyz="0 0 0"
        rpy="0 0 0" />
      <geometry>
        <mesh
          filename="package://project_two/meshes/link_4.STL" />
      </geometry>
    </collision>
  </link>
  <joint
    name="joint_4"
    type="revolute">
    <origin
      xyz="0.39225 0 0"
      rpy="0 0 0" />
    <parent
      link="link_3" />
    <child
      link="link_4" />
    <axis
      xyz="0 0 -1" />
    <limit
      lower="-3.1416"
      upper="3.1416"
      effort="0"
      velocity="0" />

      <!-- Added Joint Dynamics to Prevent Separation -->
      <dynamics damping="0.7" friction="1.0"/>
  </joint>
  <link
    name="link_4_cap">
    <inertial>
      <origin
        xyz="-0.037685 -4.2245E-09 0.11468"
        rpy="0 0 0" />
      <mass
        value="0.12996" />
      <inertia
        ixx="9.14E-05"
        ixy="1.9065E-11"
        ixz="-9.2342E-06"
        iyy="5.7055E-05"
        iyz="3.0376E-11"
        izz="6.0021E-05" />
    </inertial>
    <visual>
      <origin
        xyz="0 0 0"
        rpy="0 0 0" />
      <geometry>
        <mesh
          filename="package://project_two/meshes/link_4_cap.STL" />
      </geometry>
      <material
        name="">
        <color
          rgba="0.48235 0.79216 1 1" />
      </material>
    </visual>
    <collision>
      <origin
        xyz="0 0 0"
        rpy="0 0 0" />
      <geometry>
        <mesh
          filename="package://project_two/meshes/link_4_cap.STL" />
      </geometry>
    </collision>
  </link>
  <joint
    name="link_4_cap_joint"
    type="prismatic">
    <origin
      xyz="0 0 0"
      rpy="0 0 0" />
    <parent
      link="link_4" />
    <child
      link="link_4_cap" />
    <axis
      xyz="0 0 -1" />
    <limit
      lower="0"
      upper="0"
      effort="0"
      velocity="0" />
  </joint>
  <link
    name="link_5">
    <inertial>
      <origin
        xyz="-2.0887E-08 0.006251 0.08023"
        rpy="0 0 0" />
      <mass
        value="0.3614" />
      <inertia
        ixx="0.00034738"
        ixy="-1.8174E-10"
        ixz="4.5309E-10"
        iyy="0.00034642"
        iyz="-3.8889E-05"
        izz="0.00027444" />
    </inertial>
    <visual>
      <origin
        xyz="0 0 0"
        rpy="0 0 0" />
      <geometry>
        <mesh
          filename="package://project_two/meshes/link_5.STL" />
      </geometry>
      <material
        name="">
        <color
          rgba="0.79216 0.81961 0.93333 1" />
      </material>
    </visual>
    <collision>
      <origin
        xyz="0 0 0"
        rpy="0 0 0" />
      <geometry>
        <mesh
          filename="package://project_two/meshes/link_5.STL" />
      </geometry>
    </collision>
  </link>
  <joint
    name="joint_5"
    type="revolute">
    <origin
      xyz="0 0 0.1099"
      rpy="1.5707963267949 0 1.5707963267949" />
    <parent
      link="link_4" />
    <child
      link="link_5" />
    <axis
      xyz="0 0 -1" />
    <limit
      lower="-3.1416"
      upper="3.1416"
      effort="0"
      velocity="0" />

      <!-- Added Joint Dynamics to Prevent Separation -->
      <dynamics damping="0.7" friction="1.0"/>
  </joint>
  <link
    name="link_5_cap">
    <inertial>
      <origin
        xyz="4.2245E-09 -0.037685 0.095428"
        rpy="0 0 0" />
      <mass
        value="0.12996" />
      <inertia
        ixx="5.7055E-05"
        ixy="-1.9065E-11"
        ixz="-3.0376E-11"
        iyy="9.14E-05"
        iyz="-9.2342E-06"
        izz="6.0021E-05" />
    </inertial>
    <visual>
      <origin
        xyz="0 0 0"
        rpy="0 0 0" />
      <geometry>
        <mesh
          filename="package://project_two/meshes/link_5_cap.STL" />
      </geometry>
      <material
        name="">
        <color
          rgba="0.48235 0.79216 1 1" />
      </material>
    </visual>
    <collision>
      <origin
        xyz="0 0 0"
        rpy="0 0 0" />
      <geometry>
        <mesh
          filename="package://project_two/meshes/link_5_cap.STL" />
      </geometry>
    </collision>
  </link>
  <joint
    name="link_5_cap_joint"
    type="prismatic">
    <origin
      xyz="0 0 0"
      rpy="0 0 0" />
    <parent
      link="link_5" />
    <child
      link="link_5_cap" />
    <axis
      xyz="0 0 -1" />
    <limit
      lower="0"
      upper="0"
      effort="0"
      velocity="0" />
  </joint>
  <link
    name="link_6">
    <inertial>
      <origin
        xyz="-7.1229E-16 2.2204E-16 0.056331"
        rpy="0 0 0" />
      <mass
        value="0.14829" />
      <inertia
        ixx="7.7118E-05"
        ixy="-1.9478E-22"
        ixz="4.0506E-22"
        iyy="7.7118E-05"
        iyz="-3.0608E-20"
        izz="9.8191E-05" />
    </inertial>
    <visual>
      <origin
        xyz="0 0 0"
        rpy="0 0 0" />
      <geometry>
        <mesh
          filename="package://project_two/meshes/link_6.STL" />
      </geometry>
      <material
        name="">
        <color
          rgba="0.79216 0.81961 0.93333 1" />
      </material>
    </visual>
    <collision>
      <origin
        xyz="0 0 0"
        rpy="0 0 0" />
      <geometry>
        <mesh
          filename="package://project_two/meshes/link_6.STL" />
      </geometry>
    </collision>
  </link>
  <joint
    name="joint_6"
    type="revolute">
    <origin
      xyz="0 0 0.0906500000000001"
      rpy="-1.5707963267949 0 0" />
    <parent
      link="link_5" />
    <child
      link="link_6" />
    <axis
      xyz="0 0 -1" />
    <limit
      lower="-3.1416"
      upper="3.1416"
      effort="0"
      velocity="0" />

      <!-- Added Joint Dynamics to Prevent Separation -->
      <dynamics damping="0.7" friction="1.0"/>
  </joint>
  <link
    name="tooling_link">
    <inertial>
      <origin
        xyz="-1.5989E-18 2.2204E-16 -0.082843"
        rpy="0 0 0" />
      <mass
        value="0.12635" />
      <inertia
        ixx="0.0001347"
        ixy="8.3207E-21"
        ixz="1.1338E-20"
        iyy="0.0001347"
        iyz="-8.3871E-20"
        izz="3.2352E-05" />
    </inertial>
    <visual>
      <origin
        xyz="0 0 0"
        rpy="0 0 0" />
      <geometry>
        <mesh
          filename="package://project_two/meshes/tooling_link.STL" />
      </geometry>
      <material
        name="">
        <color
          rgba="0.19608 0.19608 0.19608 1" />
      </material>
    </visual>
    <collision>
      <origin
        xyz="0 0 0"
        rpy="0 0 0" />
      <geometry>
        <mesh
          filename="package://project_two/meshes/tooling_link.STL" />
      </geometry>
    </collision>
  </link>
  <joint
    name="tooling_joint"
    type="prismatic">
    <origin
      xyz="0 0 0.2002"
      rpy="0 0 0" />
    <parent
      link="link_6" />
    <child
      link="tooling_link" />
    <axis
      xyz="0 0 -1" />
    <limit
      lower="0"
      upper="0"
      effort="0"
      velocity="0" />
  </joint>

  <!-- Gazebo Color Plugins -->
  <gazebo reference="base_link">
    <xacro:base_color />
  </gazebo>
  <gazebo reference="link_0">
    <xacro:body_color />
  </gazebo>
  <gazebo reference="link_1">
    <xacro:body_color />
  </gazebo>
  <gazebo reference="link_2">
    <xacro:body_color />
  </gazebo>
  <gazebo reference="link_3">
    <xacro:body_color />
  </gazebo>
  <gazebo reference="link_4">
    <xacro:body_color />
  </gazebo>
  <gazebo reference="link_5">
    <xacro:body_color />
  </gazebo>
  <gazebo reference="link_6">
    <xacro:body_color />
  </gazebo>
  <gazebo reference="link_1_cap">
    <xacro:cap_color />
  </gazebo>
  <gazebo reference="link_2_cap_1">
    <xacro:cap_color />
  </gazebo>
  <gazebo reference="link_2_cap_2">
    <xacro:cap_color />
  </gazebo>
  <gazebo reference="link_3_cap">
    <xacro:cap_color />
  </gazebo>
  <gazebo reference="link_4_cap">
    <xacro:cap_color />
  </gazebo>
  <gazebo reference="link_5_cap">
    <xacro:cap_color />
  </gazebo>
  <gazebo reference="camera_link">
    <xacro:tool_color />
  </gazebo>
  <gazebo reference="tooling_link">
    <xacro:tool_color />
  </gazebo>

  <!-- Gazebo Controller Plugin -->
  <ros2_control name="GazeboSystem" type="system">
    <hardware>
      <plugin>gazebo_ros2_control/GazeboSystem</plugin>
    </hardware>
    <joint name="joint_1">
        <command_interface name="position">
            <param name="min">-3.14</param>
            <param name="max">3.14</param>
        </command_interface>
        <state_interface name="position"/>
    </joint>
    <joint name="joint_2">
        <command_interface name="position">
            <param name="min">-3.14</param>
            <param name="max">3.14</param>
        </command_interface>
        <state_interface name="position"/>
    </joint>
    <joint name="joint_3">
        <command_interface name="position">
            <param name="min">-3.14</param>
            <param name="max">3.14</param>
        </command_interface>
        <state_interface name="position"/>
    </joint>
    <joint name="joint_4">
        <command_interface name="position">
            <param name="min">-3.14</param>
            <param name="max">3.14</param>
        </command_interface>
        <state_interface name="position"/>
    </joint>
    <joint name="joint_5">
        <command_interface name="position">
            <param name="min">-3.14</param>
            <param name="max">3.14</param>
        </command_interface>
        <state_interface name="position"/>
    </joint>
    <joint name="joint_6">
        <command_interface name="position">
            <param name="min">-3.14</param>
            <param name="max">3.14</param>
        </command_interface>
        <state_interface name="position"/>
    </joint>

    <!-- Dummy Controller for Link Cap joints to instantiate in Rviz -->
    <joint name="link_1_cap_joint">
        <command_interface name="position"/>
        <state_interface name="position"/>
    </joint>
    <joint name="link_3_cap_joint">
        <command_interface name="position"/>
        <state_interface name="position"/>
    </joint>        
    <joint name="link_4_cap_joint">
        <command_interface name="position"/>
        <state_interface name="position"/>
    </joint>
    <joint name="link_5_cap_joint">
        <command_interface name="position"/>
        <state_interface name="position"/>
    </joint>
    <joint name="tooling_joint">
        <command_interface name="position"/>
        <state_interface name="position"/>
    </joint>                
    <joint name="link_2_cap_2_joint">
        <command_interface name="position"/>
        <state_interface name="position"/>
    </joint>  
    <joint name="link_2_cap_1_joint">
        <command_interface name="position"/>
        <state_interface name="position"/>
    </joint>              
    

  </ros2_control>

  <!-- Control Configuration File -->
  <gazebo>
    <plugin filename="libgazebo_ros2_control.so" name="gazebo_ros2_control">
      <parameters>$(find project_two)/config/control.yaml</parameters>
    </plugin>
  </gazebo>

  <!-- Joint Dynamics Plugins to Prevent Joint Separation -->
  <gazebo reference="joint_1">
    <implicitSpringDamper>true</implicitSpringDamper>
  </gazebo>
  <gazebo reference="joint_2">
    <implicitSpringDamper>true</implicitSpringDamper>
  </gazebo>
  <gazebo reference="joint_3">
    <implicitSpringDamper>true</implicitSpringDamper>
  </gazebo>
  <gazebo reference="joint_4">
    <implicitSpringDamper>true</implicitSpringDamper>
  </gazebo>
  <gazebo reference="joint_5">
    <implicitSpringDamper>true</implicitSpringDamper>
  </gazebo>
  <gazebo reference="joint_6">
    <implicitSpringDamper>true</implicitSpringDamper>
  </gazebo>

  <!-- Camera Sensor -->
  
  <gazebo reference="camera_link_optical">
    <sensor name="camera_sensor" type="camera">
      <pose> 0 0 0 0 0 0</pose>
      <visualize>true</visualize>
      <update_rate>10</update_rate>
      <camera>
        <horizontal_fov>1.089</horizontal_fov>
        <image>
            <format>R8G8B8</format>
            <width>640</width>
            <height>480</height>
        </image>
        <clip>
            <near>0.05</near>
            <far>20</far>
        </clip>
      </camera>

      <plugin name="camera_controller" filename="libgazebo_ros_camera.so">
        <always_on>true</always_on>
        <cameraName>camera</cameraName>
        <imageTopicName>image_raw</imageTopicName>
        <cameraInfoTopicName>camera_info</cameraInfoTopicName> 
        <frame_name>camera_link_optical</frame_name>        
      </plugin>
    </sensor>
  </gazebo>


</robot>